<?xml version="1.0" ?>
<!-- =================================================================================== -->
<!-- |    This document was autogenerated by xacro from fra2mo.urdf.xacro              | -->
<!-- |    EDITING THIS FILE BY HAND IS NOT RECOMMENDED                                 | -->
<!-- =================================================================================== -->
<robot name="fra2mo">
  <!-- Definizione dei Materiali -->
  <material name="Black">
    <color rgba="0.0 0.0 0.0 1.0"/>
  </material>
  <material name="Red">
    <color rgba="0.8 0.0 0.0 1.0"/>
  </material>
  <material name="White">
    <color rgba="1.0 1.0 1.0 1.0"/>
  </material>
  <material name="Blue">
    <color rgba="0.0 0.0 0.8 1.0"/>
  </material>
  <!--<xacro:include filename="$(find ros2_fra2mo)/urdf/utility_macro.xacro" />-->
  <!-- <xacro:include filename="$(find ros2_fra2mo)/urdf/d435_gazebo_macro.xacro" />  -->
  <!--<xacro:property name="DEPTH" value="True"/>-->
  <!--fb : front, back ; lr: left, right -->
  <!-- Actual body/chassis of the robot -->
  <link name="base_footprint">
    </link>
  <link name="base_link">
    <!-- Inertial properties -->
    <inertial>
      <origin xyz="0 0 0"/>
      <mass value="5"/>
      <inertia ixx="0.028624999999999998" ixy="0" ixz="0" iyy="0.028624999999999998" iyz="0" izz="0.030250000000000003"/>
    </inertial>
    <!-- Visual representation -->
    <visual>
      <geometry>
        <mesh filename="file:///home/user/ros2_ws/src/install/ros2_fra2mo/share/ros2_fra2mo/meshes/rl_fra2mo_body.stl" scale="0.001 0.001 0.001"/>
      </geometry>
      <material name="Blue"/>
      <origin rpy="0 0 0" xyz="0 0 0"/>
    </visual>
    <!-- Collision properties -->
    <collision>
      <geometry>
        <cylinder length="0.18" radius="0.11"/>
      </geometry>
      <origin rpy="0 0 0" xyz="0 0.0 0.039999999999999994"/>
    </collision>
    <collision>
      <geometry>
        <sphere radius="0.019"/>
      </geometry>
      <origin rpy="0 0 0" xyz="-0.0825 0.0 -0.04"/>
    </collision>
  </link>
  <!-- Left Wheel -->
  <link name="left_wheel_link">
    <visual>
      <geometry>
        <mesh filename="file:///home/user/ros2_ws/src/install/ros2_fra2mo/share/ros2_fra2mo/meshes/rl_fra2mo_wheel.stl" scale="0.001 0.001 0.001"/>
      </geometry>
      <material name="Black"/>
      <origin rpy="0 0 0" xyz="0 0 0"/>
    </visual>
    <collision>
      <geometry>
        <mesh filename="file:///home/user/ros2_ws/src/install/ros2_fra2mo/share/ros2_fra2mo/meshes/rl_fra2mo_wheel.stl" scale="0.001 0.001 0.001"/>
      </geometry>
      <origin rpy="0 0 0" xyz="0 0 0"/>
    </collision>
    <inertial>
      <origin xyz="0 0 0"/>
      <mass value="2.5"/>
      <inertia ixx="0.001" ixy="0.0" ixz="0.0" iyy="0.001" iyz="0.0" izz="0.001"/>
    </inertial>
  </link>
  <!-- Right Wheel -->
  <link name="right_wheel_link">
    <visual>
      <geometry>
        <mesh filename="file:///home/user/ros2_ws/src/install/ros2_fra2mo/share/ros2_fra2mo/meshes/rl_fra2mo_wheel.stl" scale="0.001 0.001 0.001"/>
      </geometry>
      <material name="Black"/>
      <origin rpy="0 0 0" xyz="0 0 0"/>
    </visual>
    <collision>
      <geometry>
        <mesh filename="file:///home/user/ros2_ws/src/install/ros2_fra2mo/share/ros2_fra2mo/meshes/rl_fra2mo_wheel.stl" scale="0.001 0.001 0.001"/>
      </geometry>
      <origin rpy="0 0 0" xyz="0 0 0"/>
    </collision>
    <inertial>
      <origin xyz="0 0 0"/>
      <mass value="2.5"/>
      <inertia ixx="0.001" ixy="0.0" ixz="0.0" iyy="0.001" iyz="0.0" izz="0.001"/>
    </inertial>
  </link>
  <!-- Additional Links -->
  <link name="d435_link">
    </link>
  <link name="lidar_link"/>
  <!-- Joints -->
  <joint name="base_footprint_joint" type="fixed">
    <parent link="base_footprint"/>
    <child link="base_link"/>
    <origin rpy="0 0 0" xyz="0.0 0.0 0.059"/>
  </joint>
  <joint name="left_wheel_joint" type="continuous">
    <parent link="base_link"/>
    <child link="left_wheel_link"/>
    <origin rpy="0 0 0" xyz="0.04025 0.062 -0.024"/>
    <axis xyz="0 1 0"/>
    <limit effort="100" velocity="100"/>
    <dynamics damping="0.5" friction="0.01"/>
  </joint>
  <joint name="right_wheel_joint" type="continuous">
    <parent link="base_link"/>
    <child link="right_wheel_link"/>
    <origin rpy="0 0 -3.141592653589793" xyz="0.04025 -0.062 -0.024"/>
    <axis xyz="0 -1 0"/>
    <limit effort="100" velocity="100"/>
    <dynamics damping="0.5" friction="0.01"/>
  </joint>
  <joint name="d435_joint" type="fixed">
    <parent link="base_link"/>
    <child link="d435_link"/>
    <origin rpy="0 0 0" xyz="0.090925 0.0 0.06670"/>
  </joint>
  <joint name="lidar_joint" type="fixed">
    <parent link="base_link"/>
    <child link="lidar_link"/>
    <origin rpy="0 0 0" xyz="0.0 0.0 0.125"/>
  </joint>
  <!-- Gazebo Material Assignments 
    <gazebo reference="base_link">
      <material>Gazebo/Blue</material>
    </gazebo>
    <gazebo reference="left_wheel_link">
      <material>Gazebo/Black</material>
    </gazebo>
    <gazebo reference="right_wheel_link">
      <material>Gazebo/Black</material>
    </gazebo>-->
  <!-- Transmissions -->
  <transmission name="left_wheel_joint_trans">
    <type>transmission_interface/SimpleTransmission</type>
    <joint name="left_wheel_joint"/>
    <actuator name="left_wheel_joint_motor">
      <mechanicalReduction>1</mechanicalReduction>
      <hardwareInterface>EffortJointInterface</hardwareInterface>
    </actuator>
  </transmission>
  <transmission name="right_wheel_joint_trans">
    <type>transmission_interface/SimpleTransmission</type>
    <joint name="right_wheel_joint"/>
    <actuator name="right_wheel_joint_motor">
      <mechanicalReduction>1</mechanicalReduction>
      <hardwareInterface>EffortJointInterface</hardwareInterface>
    </actuator>
  </transmission>
  <!-- Plugin for differential drive control in Gazebo-->
  <gazebo>
    <plugin filename="libignition-gazebo-diff-drive-system.so" name="ignition::gazebo::systems::DiffDrive">
      <left_joint>left_wheel_joint</left_joint>
      <right_joint>right_wheel_joint</right_joint>
      <wheel_separation>0.13</wheel_separation>
      <wheel_radius>0.035</wheel_radius>
      <!--<frame_id>base_footprint</frame_id> TO LOOK
        <ignition_frame_id>base_footprint</ignition_frame_id>-->
      <odom_publish_frequency>50</odom_publish_frequency>
      <topic>cmd_vel</topic>
    </plugin>
  </gazebo>
  <link name="laser_frame">
    <inertial>
      <origin xyz="0 0 0"/>
      <mass value="0.1"/>
      <inertia ixx="4.755833333333333e-05" ixy="0" ixz="0" iyy="4.755833333333333e-05" iyz="0" izz="6.845e-05"/>
    </inertial>
    <visual>
      <origin rpy="0 0 -1.570796327" xyz="0.0 0.0 -0.031"/>
      <geometry>
        <mesh filename="file:///home/user/ros2_ws/src/install/ros2_fra2mo/share/ros2_fra2mo/meshes/lidar.stl" scale="0.001 0.001 0.001"/>
      </geometry>
      <material name="White"/>
    </visual>
    <collision>
      <origin rpy="0 0 0" xyz="0.0 0.0 -0.031"/>
      <geometry>
        <cylinder length="0.04" radius="0.037"/>
      </geometry>
    </collision>
  </link>
  <joint name="laser_joint" type="fixed">
    <parent link="lidar_link"/>
    <child link="laser_frame"/>
    <origin rpy="0 0 0" xyz="0.0 0.0 0.031"/>
  </joint>
  <gazebo reference="laser_frame">
    <sensor name="laser_frame" type="gpu_lidar">
      <!--<pose relative_to="laser_frame">0 0 0 0 0 0</pose>-->
      <!--TO LOOK-->
      <topic>lidar</topic>
      <update_rate>10</update_rate>
      <ray>
        <scan>
          <horizontal>
            <samples>640</samples>
            <resolution>1</resolution>
            <min_angle>-3.14</min_angle>
            <max_angle>3.14</max_angle>
          </horizontal>
          <!--<vertical>
                      <samples>640</samples>
                      <resolution>1</resolution>
                      <min_angle>-1.61799</min_angle>
                      <max_angle>1.661799</max_angle>
                  </vertical>-->
        </scan>
        <range>
          <min>0.1</min>
          <max>10.0</max>
          <resolution>0.01</resolution>
        </range>
      </ray>
      <always_on>false</always_on>
      <visualize>false</visualize>
      <frame_id>laser_frame</frame_id>
      <!--TO LOOK-->
      <ignition_frame_id>laser_frame</ignition_frame_id>
    </sensor>
  </gazebo>
  <!--TO LOOK-->
  <!--<gazebo> 
    <plugin filename="libignition-gazebo-sensors-system.so" 
      name="ignition::gazebo::systems::Sensors"> 
        <render_engine>ogre2</render_engine>
    </plugin>  
  </gazebo>-->
  <gazebo>
    <plugin filename="ignition-gazebo-sensors-system" name="gz::sim::systems::Sensors"/>
  </gazebo>
  <!-- RGBD Sensor (D435 Camera) -->
  <!--
  <xacro:if value="${DEPTH}">
    <xacro:d435_gazebo_sensor parent="d435_link" />
  </xacro:if>
  -->
</robot>
